<?xml version='1.0'?>
<sdf version='1.4'>
  <model name="ITU_AGV_3">
  <static>false</static>
   
   <link name="base_link_3">
   <pose>0 0 0.12 0 0 0</pose>
   <mass>5</mass>
   
   <inertial>
        <mass>5.67</mass>
        <inertia>
          <ixx>0.07</ixx>
          <iyy>0.08</iyy>
          <izz>0.10</izz>
          <ixy>0</ixy>
          <ixz>0</ixz>
          <iyz>0</iyz>
        </inertia>
      </inertial>

   <collision name='collision'>
      <pose>0 0 -0.11 0 0 -1.571</pose>	
      <geometry>
         <mesh><uri>model://itu_agv_2/meshes/agv.stl</uri></mesh>  
      </geometry>
   </collision>
   
      <visual name="visual">
      <pose>0 0 -0.11 0 0 -1.571</pose>
      <geometry>
         <mesh><uri>model://itu_agv_2/meshes/agv.stl</uri></mesh>  
      </geometry>
   	<material>
	 <ambient>0.5 0.5 0.5 1</ambient>
	 <diffuse>0.5 0.5 0.5 1</diffuse>
	 <specular>0.1 0.1 0.1 1</specular>
	 <emissive>0 0 0 0</emissive>    
        </material>  
   </visual> 
    
   <collision name='front_caster_collision'>
	<pose>0.25 0 -0.07 0 0 0</pose>
            <geometry>
                <sphere>
                <radius>.05</radius>
              </sphere>
            </geometry>
	
	 <surface>
              <friction>
                <ode>
                  <mu>0</mu>
                  <mu2>0</mu2>
                  <slip1>1.0</slip1>
                  <slip2>1.0</slip2>
                </ode>
              </friction>
            </surface>
          </collision>
	 
	 <visual name='front_caster_visual'>
            <pose>0.25 0 -0.07 0 0 0</pose>
            <geometry>
              <sphere>
                <radius>.05</radius>
              </sphere>
            </geometry>
          </visual>

        <collision name='back_caster_collision'>
	<pose>-0.25 0 -0.07 0 0 0</pose>
            <geometry>
                <sphere>
                <radius>.05</radius>
              </sphere>
            </geometry>
	
	 <surface>
              <friction>
                <ode>
                  <mu>0</mu>
                  <mu2>0</mu2>
                  <slip1>1.0</slip1>
                  <slip2>1.0</slip2>
                </ode>
              </friction>
            </surface>
          </collision>
	 
	 <visual name='back_caster_visual'>
            <pose>-0.25 0 -0.07 0 0 0</pose>
            <geometry>
              <sphere>
                <radius>.05</radius>
              </sphere>
            </geometry>
          </visual>	

  </link> 
  
  <link name="base_footprint_3">
   <pose>0 0 0 0 0 0 </pose>
    </link>
    <joint name="base_joint" type="fixed">
      <pose>0 0 0 0 0 0 </pose>
      <parent link="base_footprint_3"/>
      <child link="base_link_3"/>
    </joint>
  
  <link name="wheel_left">
    <pose>0 0.22 0.1 1.571 0 0 </pose>
    <collision name="collision">
      <geometry>
         <cylinder>         
             <radius>.1</radius>
	     <length>.05</length>
         </cylinder>
      </geometry>
   </collision> 
  </link>
  
  <joint type="revolute" name="base_to_wheel_left">
       <pose>0 0 0 0 0 0</pose>
        <child>wheel_left</child>
        <parent>base_link_3</parent>
        <axis>
          <xyz>0 1 0</xyz>
        </axis>
      </joint>
      
    <link name="wheel_right">
    <pose>0 -0.22 0.1 1.571 0 0 </pose>
    <collision name="collision">
      <geometry>
         <cylinder>         
             <radius>.1</radius>
	     <length>.05</length>
         </cylinder>
      </geometry>
   </collision>
     
  </link>

   <joint type="revolute" name="base_to_wheel_right">
        <pose>0 0 0 0 0 0</pose>
        <child>wheel_right</child>
        <parent>base_link_3</parent>
        <axis>
          <xyz>0 1 0</xyz>
        </axis>
      </joint>  

	<plugin name="differential_drive_controller" filename="libgazebo_ros_diff_drive.so">
 		<alwaysOn>true</alwaysOn>
 		<updateRate>20</updateRate>
 		<leftJoint>base_to_wheel_left</leftJoint>
 		<rightJoint>base_to_wheel_right</rightJoint>
 		<wheelSeparation>0.4</wheelSeparation>
 		<wheelDiameter>0.2</wheelDiameter>
 		<torque>20</torque>
 		<commandTopic>cmd_vel_3</commandTopic>
 		<odometryTopic>odom</odometryTopic>
 		<odometryFrame>odom</odometryFrame>
 		<robotBaseFrame>base_footprint_3</robotBaseFrame>
 	</plugin>  
 	
   <link name="platform">
    <pose>0.12 0 0.55 0 0 0</pose>
    <visual name="visual">
     <pose>0.125 0.92 -0.4 1.571 0 0 </pose>
      <geometry>
	<mesh><uri>model://platform/meshes/platform.dae</uri></mesh>
      </geometry>
     </visual>
     
    <collision name="collision">
     <pose>0.125 0.92 -0.4 1.571 0 0 </pose>
      <geometry>
	<mesh><uri>model://platform/meshes/platform.dae</uri></mesh>
      </geometry>
     </collision> 
    </link>
  
     <joint name="base_to_platform" type="fixed" >
       <pose>0 0 0 0 0 0</pose>
        <child>platform</child>
        <parent>base_link_3</parent>
      </joint>
     
     <include>
      <uri>model://Lms 200_5</uri>
      <pose>0.32 0 0.33 0 0 0</pose>
    </include> 
    <joint name="lms_joint" type="fixed">
      <child>lms200_5::link</child>
      <parent>base_link_3</parent>
    </joint>
     
    <include>
      <uri>model://Lms 200_6</uri>
      <pose>-0.32 0 0.33 0 0 3.14</pose>
    </include> 
    <joint name="lms_joint2" type="fixed">
      <child>lms200_6::link</child>
      <parent>base_link_3</parent>
    </joint>
             
    <include>
       <uri>model://Velodyne_3</uri>
       <pose>0.12 0 0.665 1.57079633 0 0</pose>
    </include>
    <joint name="Velodyne_joint" type="fixed">
       <child>Velodyne_3::link</child>
       <parent>base_link_3</parent>
    </joint>
    
    <include>
       <uri>model://Allied Vision Mako G192C_3</uri>
       <pose>0.245 0 0.58 -1.57079633 0 -1.57079633</pose>
    </include>
    <joint name="Camera_joint" type="fixed">
       <child>Allied Vision Mako G192C_3::link</child>
       <parent>base_link_3</parent>
    </joint> 
          
  </model>	
</sdf>

